Traceback (most recent call last):
  File "/home/dan/NeurIPS2023-One-Fits-All/Long-term_Forecasting/main.py", line 127, in <module>
    train_data, train_loader = data_provider(args, 'train')
  File "/home/dan/NeurIPS2023-One-Fits-All/Long-term_Forecasting/data_provider/data_factory.py", line 40, in data_provider
    data_set = Data(
  File "/home/dan/NeurIPS2023-One-Fits-All/Long-term_Forecasting/data_provider/data_loader.py", line 44, in __init__
    self.__read_data__()
  File "/home/dan/NeurIPS2023-One-Fits-All/Long-term_Forecasting/data_provider/data_loader.py", line 54, in __read_data__
    df_raw = pd.read_csv(os.path.join(self.root_path,
  File "/home/dan/anaconda3/envs/geo/lib/python3.9/site-packages/pandas/util/_decorators.py", line 211, in wrapper
    return func(*args, **kwargs)
  File "/home/dan/anaconda3/envs/geo/lib/python3.9/site-packages/pandas/util/_decorators.py", line 331, in wrapper
    return func(*args, **kwargs)
  File "/home/dan/anaconda3/envs/geo/lib/python3.9/site-packages/pandas/io/parsers/readers.py", line 950, in read_csv
    return _read(filepath_or_buffer, kwds)
  File "/home/dan/anaconda3/envs/geo/lib/python3.9/site-packages/pandas/io/parsers/readers.py", line 605, in _read
    parser = TextFileReader(filepath_or_buffer, **kwds)
  File "/home/dan/anaconda3/envs/geo/lib/python3.9/site-packages/pandas/io/parsers/readers.py", line 1442, in __init__
    self._engine = self._make_engine(f, self.engine)
  File "/home/dan/anaconda3/envs/geo/lib/python3.9/site-packages/pandas/io/parsers/readers.py", line 1735, in _make_engine
    self.handles = get_handle(
  File "/home/dan/anaconda3/envs/geo/lib/python3.9/site-packages/pandas/io/common.py", line 856, in get_handle
    handle = open(
FileNotFoundError: [Errno 2] No such file or directory: './home/dan/NeurIPS2023-One-Fits-All/Long-term_Forecasting/dataset/ETT-small/ETTh1.csv'